2024-11-05 17:15:18,040 - app - ERROR - Internal Server Error: 500 Internal Server Error: The server encountered an internal error and was unable to complete your request. Either the server is overloaded or there is an error in the application.
2024-11-05 18:57:52,818 - app - ERROR - Exception on /github/upload [GET]
Traceback (most recent call last):
  File "/home/afael/Escritorio/EGC/GAZPACHO/gazpacho-hub/venv/lib/python3.12/site-packages/flask/app.py", line 1473, in wsgi_app
    response = self.full_dispatch_request()
               ^^^^^^^^^^^^^^^^^^^^^^^^^^^^
  File "/home/afael/Escritorio/EGC/GAZPACHO/gazpacho-hub/venv/lib/python3.12/site-packages/flask/app.py", line 882, in full_dispatch_request
    rv = self.handle_user_exception(e)
         ^^^^^^^^^^^^^^^^^^^^^^^^^^^^^
  File "/home/afael/Escritorio/EGC/GAZPACHO/gazpacho-hub/venv/lib/python3.12/site-packages/flask_restful/__init__.py", line 298, in error_router
    return original_handler(e)
           ^^^^^^^^^^^^^^^^^^^
  File "/home/afael/Escritorio/EGC/GAZPACHO/gazpacho-hub/venv/lib/python3.12/site-packages/flask/app.py", line 880, in full_dispatch_request
    rv = self.dispatch_request()
         ^^^^^^^^^^^^^^^^^^^^^^^
  File "/home/afael/Escritorio/EGC/GAZPACHO/gazpacho-hub/venv/lib/python3.12/site-packages/flask/app.py", line 865, in dispatch_request
    return self.ensure_sync(self.view_functions[rule.endpoint])(**view_args)  # type: ignore[no-any-return]
           ^^^^^^^^^^^^^^^^^^^^^^^^^^^^^^^^^^^^^^^^^^^^^^^^^^^^^^^^^^^^^^^^^
  File "/home/afael/Escritorio/EGC/GAZPACHO/gazpacho-hub/venv/lib/python3.12/site-packages/flask_login/utils.py", line 290, in decorated_view
    return current_app.ensure_sync(func)(*args, **kwargs)
           ^^^^^^^^^^^^^^^^^^^^^^^^^^^^^^^^^^^^^^^^^^^^^^
  File "/home/afael/Escritorio/EGC/GAZPACHO/gazpacho-hub/app/modules/github/routes.py", line 81, in create_dataset_github
    return render_template("upload_dataset_github.html", form=form)
           ^^^^^^^^^^^^^^^^^^^^^^^^^^^^^^^^^^^^^^^^^^^^^^^^^^^^^^^^
  File "/home/afael/Escritorio/EGC/GAZPACHO/gazpacho-hub/venv/lib/python3.12/site-packages/flask/templating.py", line 150, in render_template
    return _render(app, template, context)
           ^^^^^^^^^^^^^^^^^^^^^^^^^^^^^^^
  File "/home/afael/Escritorio/EGC/GAZPACHO/gazpacho-hub/venv/lib/python3.12/site-packages/flask/templating.py", line 131, in _render
    rv = template.render(context)
         ^^^^^^^^^^^^^^^^^^^^^^^^
  File "/home/afael/Escritorio/EGC/GAZPACHO/gazpacho-hub/venv/lib/python3.12/site-packages/jinja2/environment.py", line 1304, in render
    self.environment.handle_exception()
  File "/home/afael/Escritorio/EGC/GAZPACHO/gazpacho-hub/venv/lib/python3.12/site-packages/jinja2/environment.py", line 939, in handle_exception
    raise rewrite_traceback_stack(source=source)
  File "/home/afael/Escritorio/EGC/GAZPACHO/gazpacho-hub/app/modules/github/templates/upload_dataset_github.html", line 1, in top-level template code
    {% extends "base_template.html" %}
    ^^^^^^^^^^^^^^^^^^^^^^^^^
  File "/home/afael/Escritorio/EGC/GAZPACHO/gazpacho-hub/app/templates/base_template.html", line 207, in top-level template code
    {% block content %}{% endblock %}
    ^^^^^^^^^^^^^^^^^^^^^^^^^
  File "/home/afael/Escritorio/EGC/GAZPACHO/gazpacho-hub/app/modules/github/templates/upload_dataset_github.html", line 139, in block 'content'
    {% block scripts %}
  File "/home/afael/Escritorio/EGC/GAZPACHO/gazpacho-hub/app/modules/github/templates/upload_dataset_github.html", line 193, in block 'scripts'
    'X-CSRFToken': '{{ csrf_token() }}' // Aseg√∫rate de incluir el token CSRF si es necesario
    ^^^^^^^^^^^^^^^^^^^^^^^^^
  File "/home/afael/Escritorio/EGC/GAZPACHO/gazpacho-hub/venv/lib/python3.12/site-packages/jinja2/utils.py", line 83, in from_obj
    if hasattr(obj, "jinja_pass_arg"):
       ^^^^^^^^^^^^^^^^^^^^^^^^^^^^^^
jinja2.exceptions.UndefinedError: 'csrf_token' is undefined
2024-11-05 18:57:52,825 - app - ERROR - Internal Server Error: 500 Internal Server Error: The server encountered an internal error and was unable to complete your request. Either the server is overloaded or there is an error in the application.
2024-11-06 13:23:25,793 - app.modules.github.routes - ERROR - Exception while creating dataset or uploading to GitHub: No file part in the request
Traceback (most recent call last):
  File "/home/afael/Escritorio/EGC/GAZPACHO/gazpacho-hub/app/modules/github/routes.py", line 40, in create_dataset_github
    raise ValueError("No file part in the request")
ValueError: No file part in the request
2024-11-09 11:16:39,327 - app - ERROR - Exception on /github/dropzone [POST]
Traceback (most recent call last):
  File "/home/afael/Escritorio/EGC/GAZPACHO/gazpacho-hub/venv/lib/python3.12/site-packages/flask/app.py", line 1473, in wsgi_app
    response = self.full_dispatch_request()
               ^^^^^^^^^^^^^^^^^^^^^^^^^^^^
  File "/home/afael/Escritorio/EGC/GAZPACHO/gazpacho-hub/venv/lib/python3.12/site-packages/flask/app.py", line 882, in full_dispatch_request
    rv = self.handle_user_exception(e)
         ^^^^^^^^^^^^^^^^^^^^^^^^^^^^^
  File "/home/afael/Escritorio/EGC/GAZPACHO/gazpacho-hub/venv/lib/python3.12/site-packages/flask_restful/__init__.py", line 298, in error_router
    return original_handler(e)
           ^^^^^^^^^^^^^^^^^^^
  File "/home/afael/Escritorio/EGC/GAZPACHO/gazpacho-hub/venv/lib/python3.12/site-packages/flask/app.py", line 880, in full_dispatch_request
    rv = self.dispatch_request()
         ^^^^^^^^^^^^^^^^^^^^^^^
  File "/home/afael/Escritorio/EGC/GAZPACHO/gazpacho-hub/venv/lib/python3.12/site-packages/flask/app.py", line 865, in dispatch_request
    return self.ensure_sync(self.view_functions[rule.endpoint])(**view_args)  # type: ignore[no-any-return]
           ^^^^^^^^^^^^^^^^^^^^^^^^^^^^^^^^^^^^^^^^^^^^^^^^^^^^^^^^^^^^^^^^^
  File "/home/afael/Escritorio/EGC/GAZPACHO/gazpacho-hub/app/modules/github/routes.py", line 107, in dropzone
    file.save(file_path)
  File "/home/afael/Escritorio/EGC/GAZPACHO/gazpacho-hub/venv/lib/python3.12/site-packages/werkzeug/datastructures/file_storage.py", line 125, in save
    dst = open(dst, "wb")
          ^^^^^^^^^^^^^^^
FileNotFoundError: [Errno 2] No such file or directory: 'uploads/file7.uvl'
2024-11-09 11:16:39,337 - app - ERROR - Internal Server Error: 500 Internal Server Error: The server encountered an internal error and was unable to complete your request. Either the server is overloaded or there is an error in the application.
2024-11-09 11:17:13,460 - app - ERROR - Exception on /github/dropzone [POST]
Traceback (most recent call last):
  File "/home/afael/Escritorio/EGC/GAZPACHO/gazpacho-hub/venv/lib/python3.12/site-packages/flask/app.py", line 1473, in wsgi_app
    response = self.full_dispatch_request()
               ^^^^^^^^^^^^^^^^^^^^^^^^^^^^
  File "/home/afael/Escritorio/EGC/GAZPACHO/gazpacho-hub/venv/lib/python3.12/site-packages/flask/app.py", line 882, in full_dispatch_request
    rv = self.handle_user_exception(e)
         ^^^^^^^^^^^^^^^^^^^^^^^^^^^^^
  File "/home/afael/Escritorio/EGC/GAZPACHO/gazpacho-hub/venv/lib/python3.12/site-packages/flask_restful/__init__.py", line 298, in error_router
    return original_handler(e)
           ^^^^^^^^^^^^^^^^^^^
  File "/home/afael/Escritorio/EGC/GAZPACHO/gazpacho-hub/venv/lib/python3.12/site-packages/flask/app.py", line 880, in full_dispatch_request
    rv = self.dispatch_request()
         ^^^^^^^^^^^^^^^^^^^^^^^
  File "/home/afael/Escritorio/EGC/GAZPACHO/gazpacho-hub/venv/lib/python3.12/site-packages/flask/app.py", line 865, in dispatch_request
    return self.ensure_sync(self.view_functions[rule.endpoint])(**view_args)  # type: ignore[no-any-return]
           ^^^^^^^^^^^^^^^^^^^^^^^^^^^^^^^^^^^^^^^^^^^^^^^^^^^^^^^^^^^^^^^^^
  File "/home/afael/Escritorio/EGC/GAZPACHO/gazpacho-hub/app/modules/github/routes.py", line 107, in dropzone
    file.save(file_path)
  File "/home/afael/Escritorio/EGC/GAZPACHO/gazpacho-hub/venv/lib/python3.12/site-packages/werkzeug/datastructures/file_storage.py", line 125, in save
    dst = open(dst, "wb")
          ^^^^^^^^^^^^^^^
FileNotFoundError: [Errno 2] No such file or directory: 'uploads/file7.uvl'
2024-11-09 11:17:13,460 - app - ERROR - Internal Server Error: 500 Internal Server Error: The server encountered an internal error and was unable to complete your request. Either the server is overloaded or there is an error in the application.
