2024-11-09 11:33:06,516 - app - ERROR - Exception on /github/upload [GET]
Traceback (most recent call last):
  File "/home/afael/Escritorio/EGC/GAZPACHO/gazpacho-hub/venv/lib/python3.12/site-packages/flask/app.py", line 1473, in wsgi_app
    response = self.full_dispatch_request()
               ^^^^^^^^^^^^^^^^^^^^^^^^^^^^
  File "/home/afael/Escritorio/EGC/GAZPACHO/gazpacho-hub/venv/lib/python3.12/site-packages/flask/app.py", line 882, in full_dispatch_request
    rv = self.handle_user_exception(e)
         ^^^^^^^^^^^^^^^^^^^^^^^^^^^^^
  File "/home/afael/Escritorio/EGC/GAZPACHO/gazpacho-hub/venv/lib/python3.12/site-packages/flask_restful/__init__.py", line 298, in error_router
    return original_handler(e)
           ^^^^^^^^^^^^^^^^^^^
  File "/home/afael/Escritorio/EGC/GAZPACHO/gazpacho-hub/venv/lib/python3.12/site-packages/flask/app.py", line 880, in full_dispatch_request
    rv = self.dispatch_request()
         ^^^^^^^^^^^^^^^^^^^^^^^
  File "/home/afael/Escritorio/EGC/GAZPACHO/gazpacho-hub/venv/lib/python3.12/site-packages/flask/app.py", line 865, in dispatch_request
    return self.ensure_sync(self.view_functions[rule.endpoint])(**view_args)  # type: ignore[no-any-return]
           ^^^^^^^^^^^^^^^^^^^^^^^^^^^^^^^^^^^^^^^^^^^^^^^^^^^^^^^^^^^^^^^^^
  File "/home/afael/Escritorio/EGC/GAZPACHO/gazpacho-hub/venv/lib/python3.12/site-packages/flask_login/utils.py", line 290, in decorated_view
    return current_app.ensure_sync(func)(*args, **kwargs)
           ^^^^^^^^^^^^^^^^^^^^^^^^^^^^^^^^^^^^^^^^^^^^^^
  File "/home/afael/Escritorio/EGC/GAZPACHO/gazpacho-hub/app/modules/github/routes.py", line 81, in create_dataset_github
    return render_template("upload_dataset_github.html", form=form)
           ^^^^^^^^^^^^^^^^^^^^^^^^^^^^^^^^^^^^^^^^^^^^^^^^^^^^^^^^
  File "/home/afael/Escritorio/EGC/GAZPACHO/gazpacho-hub/venv/lib/python3.12/site-packages/flask/templating.py", line 149, in render_template
    template = app.jinja_env.get_or_select_template(template_name_or_list)
               ^^^^^^^^^^^^^^^^^^^^^^^^^^^^^^^^^^^^^^^^^^^^^^^^^^^^^^^^^^^
  File "/home/afael/Escritorio/EGC/GAZPACHO/gazpacho-hub/venv/lib/python3.12/site-packages/jinja2/environment.py", line 1084, in get_or_select_template
    return self.get_template(template_name_or_list, parent, globals)
           ^^^^^^^^^^^^^^^^^^^^^^^^^^^^^^^^^^^^^^^^^^^^^^^^^^^^^^^^^
  File "/home/afael/Escritorio/EGC/GAZPACHO/gazpacho-hub/venv/lib/python3.12/site-packages/jinja2/environment.py", line 1013, in get_template
    return self._load_template(name, globals)
           ^^^^^^^^^^^^^^^^^^^^^^^^^^^^^^^^^^
  File "/home/afael/Escritorio/EGC/GAZPACHO/gazpacho-hub/venv/lib/python3.12/site-packages/jinja2/environment.py", line 972, in _load_template
    template = self.loader.load(self, name, self.make_globals(globals))
               ^^^^^^^^^^^^^^^^^^^^^^^^^^^^^^^^^^^^^^^^^^^^^^^^^^^^^^^^
  File "/home/afael/Escritorio/EGC/GAZPACHO/gazpacho-hub/venv/lib/python3.12/site-packages/jinja2/loaders.py", line 138, in load
    code = environment.compile(source, name, filename)
           ^^^^^^^^^^^^^^^^^^^^^^^^^^^^^^^^^^^^^^^^^^^
  File "/home/afael/Escritorio/EGC/GAZPACHO/gazpacho-hub/venv/lib/python3.12/site-packages/jinja2/environment.py", line 768, in compile
    self.handle_exception(source=source_hint)
  File "/home/afael/Escritorio/EGC/GAZPACHO/gazpacho-hub/venv/lib/python3.12/site-packages/jinja2/environment.py", line 939, in handle_exception
    raise rewrite_traceback_stack(source=source)
  File "/home/afael/Escritorio/EGC/GAZPACHO/gazpacho-hub/app/modules/github/templates/upload_dataset_github.html", line 199, in template
    {% endblock %}
jinja2.exceptions.TemplateSyntaxError: Encountered unknown tag 'endblock'.
2024-11-09 11:33:06,520 - app - ERROR - Internal Server Error: 500 Internal Server Error: The server encountered an internal error and was unable to complete your request. Either the server is overloaded or there is an error in the application.
2024-11-09 11:35:04,504 - app - ERROR - Exception on /github/upload [GET]
Traceback (most recent call last):
  File "/home/afael/Escritorio/EGC/GAZPACHO/gazpacho-hub/venv/lib/python3.12/site-packages/flask/app.py", line 1473, in wsgi_app
    response = self.full_dispatch_request()
               ^^^^^^^^^^^^^^^^^^^^^^^^^^^^
  File "/home/afael/Escritorio/EGC/GAZPACHO/gazpacho-hub/venv/lib/python3.12/site-packages/flask/app.py", line 882, in full_dispatch_request
    rv = self.handle_user_exception(e)
         ^^^^^^^^^^^^^^^^^^^^^^^^^^^^^
  File "/home/afael/Escritorio/EGC/GAZPACHO/gazpacho-hub/venv/lib/python3.12/site-packages/flask_restful/__init__.py", line 298, in error_router
    return original_handler(e)
           ^^^^^^^^^^^^^^^^^^^
  File "/home/afael/Escritorio/EGC/GAZPACHO/gazpacho-hub/venv/lib/python3.12/site-packages/flask/app.py", line 880, in full_dispatch_request
    rv = self.dispatch_request()
         ^^^^^^^^^^^^^^^^^^^^^^^
  File "/home/afael/Escritorio/EGC/GAZPACHO/gazpacho-hub/venv/lib/python3.12/site-packages/flask/app.py", line 865, in dispatch_request
    return self.ensure_sync(self.view_functions[rule.endpoint])(**view_args)  # type: ignore[no-any-return]
           ^^^^^^^^^^^^^^^^^^^^^^^^^^^^^^^^^^^^^^^^^^^^^^^^^^^^^^^^^^^^^^^^^
  File "/home/afael/Escritorio/EGC/GAZPACHO/gazpacho-hub/venv/lib/python3.12/site-packages/flask_login/utils.py", line 290, in decorated_view
    return current_app.ensure_sync(func)(*args, **kwargs)
           ^^^^^^^^^^^^^^^^^^^^^^^^^^^^^^^^^^^^^^^^^^^^^^
  File "/home/afael/Escritorio/EGC/GAZPACHO/gazpacho-hub/app/modules/github/routes.py", line 81, in create_dataset_github
    return render_template("upload_dataset_github.html", form=form)
           ^^^^^^^^^^^^^^^^^^^^^^^^^^^^^^^^^^^^^^^^^^^^^^^^^^^^^^^^
  File "/home/afael/Escritorio/EGC/GAZPACHO/gazpacho-hub/venv/lib/python3.12/site-packages/flask/templating.py", line 149, in render_template
    template = app.jinja_env.get_or_select_template(template_name_or_list)
               ^^^^^^^^^^^^^^^^^^^^^^^^^^^^^^^^^^^^^^^^^^^^^^^^^^^^^^^^^^^
  File "/home/afael/Escritorio/EGC/GAZPACHO/gazpacho-hub/venv/lib/python3.12/site-packages/jinja2/environment.py", line 1084, in get_or_select_template
    return self.get_template(template_name_or_list, parent, globals)
           ^^^^^^^^^^^^^^^^^^^^^^^^^^^^^^^^^^^^^^^^^^^^^^^^^^^^^^^^^
  File "/home/afael/Escritorio/EGC/GAZPACHO/gazpacho-hub/venv/lib/python3.12/site-packages/jinja2/environment.py", line 1013, in get_template
    return self._load_template(name, globals)
           ^^^^^^^^^^^^^^^^^^^^^^^^^^^^^^^^^^
  File "/home/afael/Escritorio/EGC/GAZPACHO/gazpacho-hub/venv/lib/python3.12/site-packages/jinja2/environment.py", line 972, in _load_template
    template = self.loader.load(self, name, self.make_globals(globals))
               ^^^^^^^^^^^^^^^^^^^^^^^^^^^^^^^^^^^^^^^^^^^^^^^^^^^^^^^^
  File "/home/afael/Escritorio/EGC/GAZPACHO/gazpacho-hub/venv/lib/python3.12/site-packages/jinja2/loaders.py", line 138, in load
    code = environment.compile(source, name, filename)
           ^^^^^^^^^^^^^^^^^^^^^^^^^^^^^^^^^^^^^^^^^^^
  File "/home/afael/Escritorio/EGC/GAZPACHO/gazpacho-hub/venv/lib/python3.12/site-packages/jinja2/environment.py", line 768, in compile
    self.handle_exception(source=source_hint)
  File "/home/afael/Escritorio/EGC/GAZPACHO/gazpacho-hub/venv/lib/python3.12/site-packages/jinja2/environment.py", line 939, in handle_exception
    raise rewrite_traceback_stack(source=source)
  File "/home/afael/Escritorio/EGC/GAZPACHO/gazpacho-hub/app/modules/github/templates/upload_dataset_github.html", line 199, in template
    {% endblock %}
jinja2.exceptions.TemplateSyntaxError: Encountered unknown tag 'endblock'.
2024-11-09 11:35:04,505 - app - ERROR - Internal Server Error: 500 Internal Server Error: The server encountered an internal error and was unable to complete your request. Either the server is overloaded or there is an error in the application.
2024-11-09 11:36:26,367 - app.modules.github.routes - ERROR - Exception while creating dataset or uploading to GitHub: [Errno 2] No such file or directory: 'uploads/temp/1/file7.uvl'
Traceback (most recent call last):
  File "/home/afael/Escritorio/EGC/GAZPACHO/gazpacho-hub/app/modules/github/routes.py", line 53, in create_dataset_github
    file.save(file_path)
  File "/home/afael/Escritorio/EGC/GAZPACHO/gazpacho-hub/venv/lib/python3.12/site-packages/werkzeug/datastructures/file_storage.py", line 125, in save
    dst = open(dst, "wb")
          ^^^^^^^^^^^^^^^
FileNotFoundError: [Errno 2] No such file or directory: 'uploads/temp/1/file7.uvl'
2024-11-09 12:09:03,261 - app.modules.github.routes - ERROR - Exception while creating dataset or uploading to GitHub: 'Request' object has no attribute 'get'
Traceback (most recent call last):
  File "/home/afael/Escritorio/EGC/GAZPACHO/gazpacho-hub/app/modules/github/routes.py", line 39, in create_dataset_github
    title = request.get('title')
            ^^^^^^^^^^^
AttributeError: 'Request' object has no attribute 'get'
2024-11-09 13:06:35,625 - app - ERROR - Exception on /github/dropzone [POST]
Traceback (most recent call last):
  File "/home/afael/Escritorio/EGC/GAZPACHO/gazpacho-hub/venv/lib/python3.12/site-packages/flask/app.py", line 1473, in wsgi_app
    response = self.full_dispatch_request()
               ^^^^^^^^^^^^^^^^^^^^^^^^^^^^
  File "/home/afael/Escritorio/EGC/GAZPACHO/gazpacho-hub/venv/lib/python3.12/site-packages/flask/app.py", line 883, in full_dispatch_request
    return self.finalize_request(rv)
           ^^^^^^^^^^^^^^^^^^^^^^^^^
  File "/home/afael/Escritorio/EGC/GAZPACHO/gazpacho-hub/venv/lib/python3.12/site-packages/flask/app.py", line 902, in finalize_request
    response = self.make_response(rv)
               ^^^^^^^^^^^^^^^^^^^^^^
  File "/home/afael/Escritorio/EGC/GAZPACHO/gazpacho-hub/venv/lib/python3.12/site-packages/flask/app.py", line 1174, in make_response
    raise TypeError(
TypeError: The view function for 'github.dropzone' did not return a valid response. The function either returned None or ended without a return statement.
